2019-03-02 12:59:03.900 [error] <0.1301.0> Supervisor 'Elixir.ElasticConsumer.Supervisor' had child 'Elixir.ElasticConsumer' started with 'Elixir.ElasticConsumer':start_link() at undefined exit with reason {'EXIT',{undef,[{'Elixir.ElasticConsumer',start_link,[],[]},{supervisor,do_start_child_i,3,[{file,"supervisor.erl"},{line,379}]},{supervisor,do_start_child,2,[{file,"supervisor.erl"},{line,365}]},{supervisor,'-start_children/2-fun-0-',3,[{file,"supervisor.erl"},{line,349}]},{supervisor,children_map,4,[{file,"supervisor.erl"},{line,1157}]},{supervisor,init_children,2,[{file,"supervisor.erl"},{line,315}]},{gen_server,init_it,2,[{file,"gen_server.erl"},{line,374}]},{gen_server,init_it,6,[{file,...},...]}]}} in context start_error
2019-03-02 13:00:27.766 [error] <0.300.0>@Elixir.ElasticConsumer:init Supervisor 'Elixir.ElasticConsumer.Supervisor' had child 'Elixir.ElasticConsumer' started with 'Elixir.ElasticConsumer':start_link() at undefined exit with reason call to undefined function 'Elixir.ElasticConsumer':init([{name,'Elixir.ElasticConsumer'}]) in context start_error
2019-03-02 13:01:00.064 [error] <0.301.0>@gen_server:init_it:366 CRASH REPORT Process <0.301.0> with 0 neighbours exited with reason: bad return value: [{queue,<<"tweets">>},{exchange,<<"twitter">>},{routing_key,<<>>},{prefetch_count,<<"10">>},{uri,<<"amqp://user:bitnami@localhost:5672">>}] in gen_server:init_it/6 line 366
2019-03-22 00:34:34.963 [error] <0.304.0>@Elixir.URI:parse:445 CRASH REPORT Process <0.304.0> with 0 neighbours crashed with reason: no function clause matching 'Elixir.URI':parse(nil) line 445
2019-03-22 00:35:53.556 [error] <0.304.0>@Elixir.URI:parse:445 CRASH REPORT Process <0.304.0> with 0 neighbours crashed with reason: no function clause matching 'Elixir.URI':parse(nil) line 445
2019-03-22 00:36:59.174 [error] <0.333.0> Supervisor 'Elixir.ElasticConsumer.Supervisor' had child 'Elixir.ElasticConsumer' started with 'Elixir.ElasticConsumer':start_link() at undefined exit with reason #{'__exception__' => true,'__struct__' => 'Elixir.ArgumentError',message => <<"you must merge onto an absolute URI">>} in 'Elixir.URI':merge/2 line 551 in context start_error
